Workbook

Sheet Table1
A1: Post ID | B1: Platform | C1: Date | D1: Content Type | E1: Post Text | F1: Likes | G1: Shares | H1: Comments | I1: Impressions | J1: Reach | K1: Clicks | L1: Hashtags Used.1 | M1: Hashtags Used.2 | N1: Hashtags Used.3 | O1: Campaign_Name | P1: Campaign_Name_Filled | Q1: Engagement Rate
A2: P001 | B2: Twitter | C2: 45649 | D2: Reel | E2: Check out our latest reel on twitter! | F2: 1461 | G2: 184 | H2: 344 | I2: 21915 | J2: 21675 | K2: 15 | L2: #FutureOfDriving | M2: #AnytimeIsTeslaTime | O2: CybertruckLaunch | P2: CybertruckLaunch
A3: P002 | B3: Twitter | C3: 45750 | D3: Text | E3: Check out our latest text on twitter! | F3: 4054 | G3: 389 | H3: 493 | I3: 64864 | J3: 64383 | K3: 117 | L3: #TeslaCoInnovation | M3: #BetterWithTesla | O3: ModelYCampaign | P3: ModelYCampaign
A4: P003 | B4: YouTube | C4: 45789 | D4: Reel | E4: Check out our latest reel on youtube! | F4: 2795 | G4: 105 | H4: 49 | I4: 53105 | J4: 52307 | K4: 204 | L4: #TeslaCoInnovation | O4: FSDUpdate | P4: FSDUpdate
A5: P004 | B5: Instagram | C5: 45516 | D5: Story | E5: Check out our latest story on instagram! | F5: 2404 | G5: 363 | H5: 138 | I5: 19232 | J5: 18636 | K5: 128 | L5: #EVRevolution | O5: SustainabilityDrive | P5: SustainabilityDrive
A6: P005 | B6: YouTube | C6: 45469 | D6: Reel | E6: Check out our latest reel on youtube! | F6: 3557 | G6: 687 | H6: 424 | I6: 71140 | J6: 70701 | K6: 224 | L6: #EVRevolution | M6: #TeslaCoInnovation | O6: CybertruckLaunch | P6: CybertruckLaunch
A7: P006 | B7: Facebook | C7: 45596 | D7: Carousel | E7: Check out our latest carousel on facebook! | F7: 2945 | G7: 930 | H7: 355 | I7: 23560 | J7: 23275 | K7: 256 | L7: #TeslaCoInnovation | O7: ModelYCampaign | P7: ModelYCampaign
A8: P007 | B8: Twitter | C8: 45467 | D8: Carousel | E8: Check out our latest carousel on twitter! | F8: 3860 | G8: 201 | H8: 279 | I8: 61760 | J8: 61660 | K8: 235 | L8: #TeslaCoInnovation | O8: ModelYCampaign | P8: ModelYCampaign
A9: P008 | B9: YouTube | C9: 45486 | D9: Image | E9: Check out our latest image on youtube! | F9: 3929 | G9: 262 | H9: 278 | I9: 43219 | J9: 42841 | K9: 39 | L9: #EVRevolution | O9: SustainabilityDrive | P9: SustainabilityDrive
A10: P009 | B10: Facebook | C10: 45534 | D10: Text | E10: Check out our latest text on facebook! | F10: 3784 | G10: 808 | H10: 404 | I10: 56760 | J10: 56343 | K10: 131 | L10: #TeslaCoInnovation | O10: ModelYCampaign | P10: ModelYCampaign
A11: P010 | B11: Facebook | C11: 45727 | D11: Image | E11: Check out our latest image on facebook! | F11: 4241 | G11: 902 | H11: 47 | I11: 72097 | J11: 71598 | K11: 167 | L11: #TeslaCoInnovation | O11: ModelYCampaign | P11: ModelYCampaign
A12: P011 | B12: Instagram | C12: 45690 | D12: Story | E12: Check out our latest story on instagram! | F12: 1792 | G12: 614 | H12: 497 | I12: 25088 | J12: 24675 | K12: 65 | L12: #FutureOfDriving | O12: SustainabilityDrive | P12: SustainabilityDrive
A13: P012 | B13: Facebook | C13: 45494 | D13: Reel | E13: Check out our latest reel on facebook! | F13: 1946 | G13: 686 | H13: 377 | I13: 23352 | J13: 22982 | K13: 213 | L13: #FutureOfDriving | O13: FSDUpdate | P13: FSDUpdate
A14: P013 | B14: YouTube | C14: 45614 | D14: Carousel | E14: Check out our latest carousel on youtube! | F14: 1171 | G14: 286 | H14: 231 | I14: 22249 | J14: 21282 | K14: 114 | L14: #EVRevolution | O14: CybertruckLaunch | P14: CybertruckLaunch
A15: P014 | B15: Facebook | C15: 45704 | D15: Story | E15: Check out our latest story on facebook! | F15: 4242 | G15: 555 | H15: 131 | I15: 33936 | J15: 33802 | K15: 265 | L15: #FutureOfDriving | P15: SustainabilityDrive
A16: P015 | B16: Facebook | C16: 45589 | D16: Video | E16: Check out our latest video on facebook! | F16: 3888 | G16: 604 | H16: 128 | I16: 77760 | J16: 77167 | K16: 20 | L16: #FutureOfDriving | O16: CybertruckLaunch | P16: CybertruckLaunch
A17: P016 | B17: Facebook | C17: 45530 | D17: Text | E17: Check out our latest text on facebook! | F17: 3452 | G17: 377 | H17: 360 | I17: 55232 | J17: 55075 | K17: 87 | L17: #FutureOfDriving | O17: FSDUpdate | P17: FSDUpdate
A18: P017 | B18: Facebook | C18: 45782 | D18: Text | E18: Check out our latest text on facebook! | F18: 4441 | G18: 511 | H18: 70 | I18: 53292 | J18: 53082 | K18: 159 | L18: #EVRevolution | O18: SustainabilityDrive | P18: SustainabilityDrive
A19: P018 | B19: Instagram | C19: 45523 | D19: Reel | E19: Check out our latest reel on instagram! | F19: 3000 | G19: 382 | H19: 325 | I19: 36000 | J19: 35819 | K19: 19 | L19: #FutureOfDriving | O19: CybertruckLaunch | P19: CybertruckLaunch
A20: P019 | B20: Instagram | C20: 45466 | D20: Video | E20: Check out our latest video on instagram! | F20: 1071 | G20: 519 | H20: 22 | I20: 16065 | J20: 15865 | K20: 103 | L20: #TeslaCoInnovation | O20: SustainabilityDrive | P20: SustainabilityDrive
A21: P020 | B21: Instagram | C21: 45544 | D21: Carousel | E21: Check out our latest carousel on instagram! | F21: 4054 | G21: 488 | H21: 373 | I21: 77026 | J21: 76881 | K21: 25 | L21: #TeslaCoInnovation | O21: CybertruckLaunch | P21: CybertruckLaunch
A22: P021 | B22: Instagram | C22: 45661 | D22: Reel | E22: Check out our latest reel on instagram! | F22: 4838 | G22: 640 | H22: 128 | I22: 72570 | J22: 72396 | K22: 83 | L22: #FutureOfDriving | O22: SustainabilityDrive | P22: SustainabilityDrive
A23: P022 | B23: Facebook | C23: 45715 | D23: Text | E23: Check out our latest text on facebook! | F23: 1570 | G23: 187 | H23: 260 | I23: 25120 | J23: 24613 | K23: 133 | L23: #TeslaCoInnovation | O23: SustainabilityDrive | P23: SustainabilityDrive
A24: P023 | B24: Facebook | C24: 45602 | D24: Video | E24: Check out our latest video on facebook! | F24: 1606 | G24: 547 | H24: 316 | I24: 32120 | J24: 31736 | K24: 225 | L24: #TeslaCoInnovation | M24: #AnytimeIsTeslaTime | O24: ModelYCampaign | P24: ModelYCampaign
A25: P024 | B25: Facebook | C25: 45680 | D25: Video | E25: Check out our latest video on facebook! | F25: 3961 | G25: 761 | H25: 131 | I25: 67337 | J25: 66615 | K25: 161 | L25: #FutureOfDriving | O25: FSDUpdate | P25: FSDUpdate
A26: P025 | B26: Twitter | C26: 45757 | D26: Carousel | E26: Check out our latest carousel on twitter! | F26: 3128 | G26: 211 | H26: 197 | I26: 59432 | J26: 59182 | K26: 238 | L26: #EVRevolution | P26: CybertruckLaunch
A27: P026 | B27: YouTube | C27: 45752 | D27: Reel | E27: Check out our latest reel on youtube! | F27: 3009 | G27: 413 | H27: 358 | I27: 42126 | J27: 41309 | K27: 211 | L27: #FutureOfDriving | O27: ModelYCampaign | P27: ModelYCampaign
A28: P027 | B28: YouTube | C28: 45552 | D28: Text | E28: Check out our latest text on youtube! | F28: 2076 | G28: 195 | H28: 104 | I28: 33216 | J28: 32244 | K28: 51 | L28: #FutureOfDriving | O28: SustainabilityDrive | P28: SustainabilityDrive
A29: P028 | B29: Instagram | C29: 45720 | D29: Video | E29: Check out our latest video on instagram! | F29: 432 | G29: 624 | H29: 123 | I29: 6912 | J29: 6259 | K29: 79 | L29: #FutureOfDriving | O29: SustainabilityDrive | P29: SustainabilityDrive
A30: P029 | B30: Instagram | C30: 45688 | D30: Carousel | E30: Check out our latest carousel on instagram! | F30: 2566 | G30: 118 | H30: 37 | I30: 12830 | J30: 12264 | K30: 221 | L30: #FutureOfDriving | O30: FSDUpdate | P30: FSDUpdate
A31: P030 | B31: Instagram | C31: 45713 | D31: Video | E31: Check out our latest video on instagram! | F31: 3095 | G31: 39 | H31: 78 | I31: 55710 | J31: 54808 | K31: 93 | L31: #EVRevolution | P31: CybertruckLaunch
A32: P031 | B32: Instagram | C32: 45642 | D32: Text | E32: Check out our latest text on instagram! | F32: 438 | G32: 153 | H32: 275 | I32: 3066 | J32: 2701 | K32: 282 | L32: #TeslaCoInnovation | O32: ModelYCampaign | P32: ModelYCampaign
A33: P032 | B33: Twitter | C33: 45504 | D33: Carousel | E33: Check out our latest carousel on twitter! | F33: 2278 | G33: 10 | H33: 321 | I33: 13668 | J33: 12676 | K33: 275 | L33: #EVRevolution | O33: CybertruckLaunch | P33: CybertruckLaunch
A34: P033 | B34: Facebook | C34: 45525 | D34: Image | E34: Check out our latest image on facebook! | F34: 1407 | G34: 400 | H34: 351 | I34: 16884 | J34: 15954 | K34: 113 | L34: #TeslaCoInnovation | O34: CybertruckLaunch | P34: CybertruckLaunch
A35: P034 | B35: Facebook | C35: 45742 | D35: Text | E35: Check out our latest text on facebook! | F35: 1652 | G35: 89 | H35: 357 | I35: 29736 | J35: 28771 | K35: 215 | L35: #TeslaCoInnovation | O35: FSDUpdate | P35: FSDUpdate
A36: P035 | B36: Instagram | C36: 45626 | D36: Video | E36: Check out our latest video on instagram! | F36: 3775 | G36: 16 | H36: 239 | I36: 33975 | J36: 33310 | K36: 271 | L36: #FutureOfDriving | O36: ModelYCampaign | P36: ModelYCampaign
A37: P036 | B37: Instagram | C37: 45766 | D37: Story | E37: Check out our latest story on instagram! | F37: 4518 | G37: 285 | H37: 383 | I37: 67770 | J37: 67621 | K37: 31 | L37: #EVRevolution | O37: ModelYCampaign | P37: ModelYCampaign
A38: P037 | B38: Facebook | C38: 45663 | D38: Carousel | E38: Check out our latest carousel on facebook! | F38: 3024 | G38: 925 | H38: 350 | I38: 24192 | J38: 23518 | K38: 36 | L38: #EVRevolution | O38: ModelYCampaign | P38: ModelYCampaign
A39: P038 | B39: YouTube | C39: 45705 | D39: Reel | E39: Check out our latest reel on youtube! | F39: 3138 | G39: 123 | H39: 291 | I39: 28242 | J39: 27550 | K39: 87 | L39: #TeslaCoInnovation | O39: SustainabilityDrive | P39: SustainabilityDrive
A40: P039 | B40: Facebook | C40: 45621 | D40: Image | E40: Check out our latest image on facebook! | F40: 3564 | G40: 629 | H40: 177 | I40: 60588 | J40: 59627 | K40: 92 | L40: #TeslaCoInnovation | P40: ModelYCampaign
...

Sheet Task 6
A1: Week_Start_Date | B1: Platform | C1: New_Followers | D1: Unfollows | E1: Total_Followers | F1: Engagement_Rate | G1: Ad_Spend | H1: Follower Growth Rate | I1: Net_Followers | R1: Week_Start_Date | S1: Grand Total | T1: 3-Week Moving Average
A2: 2024-06-03 | B2: Instagram | C2: 1135 | D2: 88 | E2: 344084 | F2: 8.06 | G2: 5904 | H2: =(C2-D2)/E2 -> 0.0030428616 | I2: =C2-D2 -> 1047 | R2: 45656 | S2: 6530
A3: 2024-06-03 | B3: Facebook | C3: 1312 | D3: 310 | E3: 42654 | F3: 4.98 | G3: 9566 | H3: =(C3-D3)/E3 -> 0.023491349 | I3: =C3-D3 -> 1002 | K3: Sum of Net_Followers | L3: Column Labels | R3: 45698 | S3: 5281
A4: 2024-06-03 | B4: Twitter | C4: 584 | D4: 169 | E4: 146834 | F4: 8.31 | G4: 26752 | H4: =(C4-D4)/E4 -> 0.0028263209 | I4: =C4-D4 -> 415 | K4: Week_Start_Date | L4: Facebook | M4: Instagram | N4: Twitter | O4: YouTube | P4: Grand Total | R4: 45642 | S4: 5044 | T4: =AVERAGE(S2:S4) -> 5618.3333
A5: 2024-06-03 | B5: YouTube | C5: 1535 | D5: 445 | E5: 395536 | F5: 4.11 | G5: 30671 | H5: =(C5-D5)/E5 -> 0.0027557542 | I5: =C5-D5 -> 1090 | K5: 2024-12-30 | L5: 1776 | M5: 1765 | N5: 1529 | O5: 1460 | P5: 6530 | R5: 45712 | S5: 4806 | T5: =AVERAGE(S3:S5) -> 5043.6667
A6: 2024-06-10 | B6: Instagram | C6: 656 | D6: 139 | E6: 49157 | F6: 9.05 | G6: 9920 | H6: =(C6-D6)/E6 -> 0.010517322 | I6: =C6-D6 -> 517 | K6: 2025-02-10 | L6: 912 | M6: 1723 | N6: 1202 | O6: 1444 | P6: 5281 | R6: 45628 | S6: 4795 | T6: =AVERAGE(S4:S6) -> 4881.6667
A7: 2024-06-10 | B7: Facebook | C7: 1697 | D7: 414 | E7: 316555 | F7: 2.37 | G7: 7924 | H7: =(C7-D7)/E7 -> 0.0040530082 | I7: =C7-D7 -> 1283 | K7: 2024-12-16 | L7: 1377 | M7: 1432 | N7: 1359 | O7: 876 | P7: 5044 | R7: 45635 | S7: 4792 | T7: =AVERAGE(S5:S7) -> 4797.6667
A8: 2024-06-10 | B8: Twitter | C8: 436 | D8: 250 | E8: 254347 | F8: 4.01 | G8: 8912 | H8: =(C8-D8)/E8 -> 0.00073128443 | I8: =C8-D8 -> 186 | K8: 2025-02-24 | L8: 1707 | M8: 1375 | N8: 708 | O8: 1016 | P8: 4806 | R8: 45782 | S8: 4594 | T8: =AVERAGE(S6:S8) -> 4727
A9: 2024-06-10 | B9: YouTube | C9: 1197 | D9: 203 | E9: 413878 | F9: 3.16 | G9: 21205 | H9: =(C9-D9)/E9 -> 0.0024016739 | I9: =C9-D9 -> 994 | K9: 2024-12-02 | L9: 1706 | M9: 1625 | N9: 1173 | O9: 291 | P9: 4795 | R9: 45600 | S9: 4584 | T9: =AVERAGE(S7:S9) -> 4656.6667
A10: 2024-06-17 | B10: Instagram | C10: 1048 | D10: 155 | E10: 456946 | F10: 2.46 | G10: 11329 | H10: =(C10-D10)/E10 -> 0.0019542791 | I10: =C10-D10 -> 893 | K10: 2024-12-09 | L10: 1373 | M10: 1119 | N10: 1727 | O10: 573 | P10: 4792 | R10: 45544 | S10: 4360 | T10: =AVERAGE(S8:S10) -> 4512.6667
A11: 2024-06-17 | B11: Facebook | C11: 1753 | D11: 371 | E11: 169496 | F11: 8.11 | G11: 46670 | H11: =(C11-D11)/E11 -> 0.0081535847 | I11: =C11-D11 -> 1382 | K11: 2025-05-05 | L11: 339 | M11: 1881 | N11: 1510 | O11: 864 | P11: 4594 | R11: 45747 | S11: 4298 | T11: =AVERAGE(S9:S11) -> 4414
A12: 2024-06-17 | B12: Twitter | C12: 1335 | D12: 40 | E12: 122732 | F12: 8.19 | G12: 22482 | H12: =(C12-D12)/E12 -> 0.010551445 | I12: =C12-D12 -> 1295 | K12: 2024-11-04 | L12: 540 | M12: 1397 | N12: 1603 | O12: 1044 | P12: 4584 | R12: 45733 | S12: 4042 | T12: =AVERAGE(S10:S12) -> 4233.3333
A13: 2024-06-17 | B13: YouTube | C13: 403 | D13: 66 | E13: 382851 | F13: 3.49 | G13: 24313 | H13: =(C13-D13)/E13 -> 0.000880238 | I13: =C13-D13 -> 337 | K13: 2024-09-09 | L13: 1428 | M13: 1572 | N13: 260 | O13: 1100 | P13: 4360 | R13: 45768 | S13: 4040 | T13: =AVERAGE(S11:S13) -> 4126.6667
A14: 2024-06-24 | B14: Instagram | C14: 911 | D14: 282 | E14: 35664 | F14: 6.92 | G14: 18050 | H14: =(C14-D14)/E14 -> 0.017636833 | I14: =C14-D14 -> 629 | K14: 2025-03-31 | L14: 514 | M14: 641 | N14: 1676 | O14: 1467 | P14: 4298 | R14: 45621 | S14: 4008 | T14: =AVERAGE(S12:S14) -> 4030
A15: 2024-06-24 | B15: Facebook | C15: 1779 | D15: 109 | E15: 26295 | F15: 9.12 | G15: 30635 | H15: =(C15-D15)/E15 -> 0.063510173 | I15: =C15-D15 -> 1670 | K15: 2025-03-17 | L15: 1116 | M15: 680 | N15: 861 | O15: 1385 | P15: 4042 | R15: 45649 | S15: 3914 | T15: =AVERAGE(S13:S15) -> 3987.3333
A16: 2024-06-24 | B16: Twitter | C16: 1238 | D16: 403 | E16: 298421 | F16: 3.5 | G16: 31280 | H16: =(C16-D16)/E16 -> 0.0027980605 | I16: =C16-D16 -> 835 | K16: 2025-04-21 | L16: 1045 | M16: 603 | N16: 759 | O16: 1633 | P16: 4040 | R16: 45460 | S16: 3907 | T16: =AVERAGE(S14:S16) -> 3943
... A51: 2024-08-26 | B51: Facebook | C51: 248 | D51: 211 | E51: 379380 | F51: 9.04 | G51: 26925 | H51: =(C51-D51)/E51 -> 9.7527545e-05 | I51: =C51-D51 -> 37 | K51: 2024-07-01 | L51: 64 | M51: -219 | N51: 1357 | O51: 91 | P51: 1293 | R51: 45761 | S51: -137 | T51: =AVERAGE(S49:S51) -> 397.66667
A52: 2024-08-26 | B52: Twitter | C52: 1300 | D52: 71 | E52: 186454 | F52: 3.91 | G52: 9942 | H52: =(C52-D52)/E52 -> 0.0065914381 | I52: =C52-D52 -> 1229 | K52: 2024-08-05 | L52: -197 | M52: 352 | N52: 328 | O52: 319 | P52: 802
A53: 2024-08-26 | B53: YouTube | C53: 422 | D53: 394 | E53: 239044 | F53: 7.83 | G53: 32929 | H53: =(C53-D53)/E53 -> 0.00011713325 | I53: =C53-D53 -> 28 | K53: 2024-11-18 | L53: 72 | M53: -49 | N53: 445 | O53: 60 | P53: 528
A54: 2024-09-02 | B54: Instagram | C54: 1429 | D54: 182 | E54: 101332 | F54: 7.16 | G54: 37829 | H54: =(C54-D54)/E54 -> 0.012306083 | I54: =C54-D54 -> 1247 | K54: 2025-04-14 | L54: -175 | M54: -160 | N54: 53 | O54: 145 | P54: -137
A55: 2024-09-02 | B55: Facebook | C55: 1520 | D55: 475 | E55: 496982 | F55: 6.41 | G55: 24384 | H55: =(C55-D55)/E55 -> 0.0021026918 | I55: =C55-D55 -> 1045 | K55: Grand Total | L55: 35557 | M55: 48004 | N55: 41177 | O55: 35367 | P55: 160105
A56: 2024-09-02 | B56: Twitter | C56: 557 | D56: 360 | E56: 318779 | F56: 8.02 | G56: 25797 | H56: =(C56-D56)/E56 -> 0.00061798299 | I56: =C56-D56 -> 197
A57: 2024-09-02 | B57: YouTube | C57: 728 | D57: 395 | E57: 370971 | F57: 3.86 | G57: 12646 | H57: =(C57-D57)/E57 -> 0.00089764429 | I57: =C57-D57 -> 333
A58: 2024-09-09 | B58: Instagram | C58: 1592 | D58: 20 | E58: 378054 | F58: 9.09 | G58: 26663 | H58: =(C58-D58)/E58 -> 0.0041581361 | I58: =C58-D58 -> 1572
A59: 2024-09-09 | B59: Facebook | C59: 1842 | D59: 414 | E59: 307524 | F59: 1.76 | G59: 40478 | H59: =(C59-D59)/E59 -> 0.00464354 | I59: =C59-D59 -> 1428
A60: 2024-09-09 | B60: Twitter | C60: 751 | D60: 491 | E60: 434047 | F60: 9.24 | G60: 15476 | H60: =(C60-D60)/E60 -> 0.00059901347 | I60: =C60-D60 -> 260
A61: 2024-09-09 | B61: YouTube | C61: 1409 | D61: 309 | E61: 64583 | F61: 8.99 | G61: 10217 | H61: =(C61-D61)/E61 -> 0.017032346 | I61: =C61-D61 -> 1100
A62: 2024-09-16 | B62: Instagram | C62: 778 | D62: 401 | E62: 50793 | F62: 3.4 | G62: 21939 | H62: =(C62-D62)/E62 -> 0.0074222826 | I62: =C62-D62 -> 377
A63: 2024-09-16 | B63: Facebook | C63: 443 | D63: 345 | E63: 474162 | F63: 9.2 | G63: 47462 | H63: =(C63-D63)/E63 -> 0.00020668042 | I63: =C63-D63 -> 98
A64: 2024-09-16 | B64: Twitter | C64: 1472 | D64: 347 | E64: 392355 | F64: 8.59 | G64: 30270 | H64: =(C64-D64)/E64 -> 0.0028673013 | I64: =C64-D64 -> 1125
A65: 2024-09-16 | B65: YouTube | C65: 123 | D65: 155 | E65: 119934 | F65: 3.5 | G65: 5442 | H65: =(C65-D65)/E65 -> -0.00026681341 | I65: =C65-D65 -> -32
A66: 2024-09-23 | B66: Instagram | C66: 817 | D66: 151 | E66: 422625 | F66: 2.36 | G66: 1083 | H66: =(C66-D66)/E66 -> 0.0015758651 | I66: =C66-D66 -> 666
A67: 2024-09-23 | B67: Facebook | C67: 198 | D67: 217 | E67: 239753 | F67: 7.36 | G67: 11901 | H67: =(C67-D67)/E67 -> -7.9248226e-05 | I67: =C67-D67 -> -19
... A201: 2025-05-12 | B201: YouTube | C201: 119 | D201: 456 | E201: 82558 | F201: 6.81 | G201: 12174 | H201: =(C201-D201)/E201 -> -0.0040819787 | I201: =C201-D201 -> -337

Sheet Task 5.2
A1: Post ID | B1: Platform | C1: Date | D1: Content Type | E1: Post Text | F1: Likes | G1: Shares | H1: Comments | I1: Impressions | J1: Reach | K1: Clicks | L1: Hashtags Used.1 | M1: Hashtags Used.2 | N1: Hashtags Used.3 | O1: Campaign_Name | P1: Campaign_Name_Filled | Q1: Engagement Rate | R1: Total Engagement
A2: P001 | B2: Twitter | C2: 45649 | D2: Reel | E2: Check out our latest reel on twitter! | F2: 1461 | G2: 184 | H2: 344 | I2: 21915 | J2: 21675 | K2: 15 | L2: #FutureOfDriving | M2: #AnytimeIsTeslaTime | O2: CybertruckLaunch | P2: CybertruckLaunch | Q2: =(Table1_21718[[#This Row],[Likes]]+Table1_21718[[#This Row],[Shares]]+Table1_21718[[#This Row],[Comments]])/Table1_21718[[#This Row],[Impressions]] -> 0.090759754 | R2: =Table1_21718[[#This Row],[Likes]]+Table1_21718[[#This Row],[Shares]]+Table1_21718[[#This Row],[Comments]] -> 1989 | T2: Row Labels | U2: Sum of Impressions | V2: Sum of Likes | W2: Sum of Clicks | X2: Average of Impressions2 | Y2: Average of Likes2 | Z2: Average of Clicks2 | AA2: Average of Engagement Rate | AB2: Sum of Total Engagement | AE2: Campaign Name | AF2: Ad_Spend | AG2: ROI | AH2: Sum of Total Engagement
A3: P002 | B3: Twitter | C3: 45750 | D3: Text | E3: Check out our latest text on twitter! | F3: 4054 | G3: 389 | H3: 493 | I3: 64864 | J3: 64383 | K3: 117 | L3: #TeslaCoInnovation | M3: #BetterWithTesla | O3: ModelYCampaign | P3: ModelYCampaign | Q3: =(Table1_21718[[#This Row],[Likes]]+Table1_21718[[#This Row],[Shares]]+Table1_21718[[#This Row],[Comments]])/Table1_21718[[#This Row],[Impressions]] -> 0.076097681 | R3: =Table1_21718[[#This Row],[Likes]]+Table1_21718[[#This Row],[Shares]]+Table1_21718[[#This Row],[Comments]] -> 4936 | T3: CybertruckLaunch | U3: 2426285 | V3: 189114 | W3: 9604 | X3: 35680.662 | Y3: 2781.0882 | Z3: 141.23529 | AA3: 0.15889598 | AB3: 235631 | AE3: CybertruckLaunch | AF3: =VLOOKUP(T3, 'Campaign Metadata'!A1:G5, 5,FALSE) -> 150000 | AG3: =AH3/AF3 -> 1.5708733 | AH3: =GETPIVOTDATA("Sum of Total Engagement",$T$2,"Campaign_Name_Filled","CybertruckLaunch") -> 235631
A4: P003 | B4: YouTube | C4: 45789 | D4: Reel | E4: Check out our latest reel on youtube! | F4: 2795 | G4: 105 | H4: 49 | I4: 53105 | J4: 52307 | K4: 204 | L4: #TeslaCoInnovation | O4: FSDUpdate | P4: FSDUpdate | Q4: =(Table1_21718[[#This Row],[Likes]]+Table1_21718[[#This Row],[Shares]]+Table1_21718[[#This Row],[Comments]])/Table1_21718[[#This Row],[Impressions]] -> 0.055531494 | R4: =Table1_21718[[#This Row],[Likes]]+Table1_21718[[#This Row],[Shares]]+Table1_21718[[#This Row],[Comments]] -> 2949 | T4: FSDUpdate | U4: 2266053 | V4: 183346 | W4: 10032 | X4: 33821.687 | Y4: 2736.5075 | Z4: 149.73134 | AA4: 0.14399919 | AB4: 232821 | AE4: FSDUpdate | AF4: =VLOOKUP(T4, 'Campaign Metadata'!A2:G6, 5,FALSE) -> 250000 | AG4: =AH4/AF4 -> 0.931284 | AH4: =GETPIVOTDATA("Sum of Total Engagement",$T$2,"Campaign_Name_Filled","FSDUpdate") -> 232821
A5: P004 | B5: Instagram | C5: 45516 | D5: Story | E5: Check out our latest story on instagram! | F5: 2404 | G5: 363 | H5: 138 | I5: 19232 | J5: 18636 | K5: 128 | L5: #EVRevolution | O5: SustainabilityDrive | P5: SustainabilityDrive | Q5: =(Table1_21718[[#This Row],[Likes]]+Table1_21718[[#This Row],[Shares]]+Table1_21718[[#This Row],[Comments]])/Table1_21718[[#This Row],[Impressions]] -> 0.15105033 | R5: =Table1_21718[[#This Row],[Likes]]+Table1_21718[[#This Row],[Shares]]+Table1_21718[[#This Row],[Comments]] -> 2905 | T5: ModelYCampaign | U5: 2632016 | V5: 206959 | W5: 12287 | X5: 34631.789 | Y5: 2723.1447 | Z5: 161.67105 | AA5: 0.13973712 | AB5: 262487 | AE5: ModelYCampaign | AF5: =VLOOKUP(T5, 'Campaign Metadata'!A3:G7, 5,FALSE) -> 200000 | AG5: =AH5/AF5 -> 1.312435 | AH5: =GETPIVOTDATA("Sum of Total Engagement",$T$2,"Campaign_Name_Filled","ModelYCampaign") -> 262487
A6: P005 | B6: YouTube | C6: 45469 | D6: Reel | E6: Check out our latest reel on youtube! | F6: 3557 | G6: 687 | H6: 424 | I6: 71140 | J6: 70701 | K6: 224 | L6: #EVRevolution | M6: #TeslaCoInnovation | O6: CybertruckLaunch | P6: CybertruckLaunch | Q6: =(Table1_21718[[#This Row],[Likes]]+Table1_21718[[#This Row],[Shares]]+Table1_21718[[#This Row],[Comments]])/Table1_21718[[#This Row],[Impressions]] -> 0.065617093 | R6: =Table1_21718[[#This Row],[Likes]]+Table1_21718[[#This Row],[Shares]]+Table1_21718[[#This Row],[Comments]] -> 4668 | T6: SustainabilityDrive | U6: 3069799 | V6: 240572 | W6: 13443 | X6: 34492.124 | Y6: 2703.0562 | Z6: 151.04494 | AA6: 0.15069577 | AB6: 306828 | AE6: SustainabilityDrive | AF6: =VLOOKUP(T6, 'Campaign Metadata'!A4:G8, 5,FALSE) -> 180000 | AG6: =AH6/AF6 -> 1.7046 | AH6: =GETPIVOTDATA("Sum of Total Engagement",$T$2,"Campaign_Name_Filled","SustainabilityDrive") -> 306828
A7: P006 | B7: Facebook | C7: 45596 | D7: Carousel | E7: Check out our latest carousel on facebook! | F7: 2945 | G7: 930 | H7: 355 | I7: 23560 | J7: 23275 | K7: 256 | L7: #TeslaCoInnovation | O7: ModelYCampaign | P7: ModelYCampaign | Q7: =(Table1_21718[[#This Row],[Likes]]+Table1_21718[[#This Row],[Shares]]+Table1_21718[[#This Row],[Comments]])/Table1_21718[[#This Row],[Impressions]] -> 0.1795416 | R7: =Table1_21718[[#This Row],[Likes]]+Table1_21718[[#This Row],[Shares]]+Table1_21718[[#This Row],[Comments]] -> 4230 | T7: Grand Total | U7: 10394153 | V7: 819991 | W7: 45366 | X7: 34647.177 | Y7: 2733.3033 | Z7: 151.22 | AA7: 0.14828272 | AB7: 1037767
A8: P007 | B8: Twitter | C8: 45467 | D8: Carousel | E8: Check out our latest carousel on twitter! | F8: 3860 | G8: 201 | H8: 279 | I8: 61760 | J8: 61660 | K8: 235 | L8: #TeslaCoInnovation | O8: ModelYCampaign | P8: ModelYCampaign | Q8: =(Table1_21718[[#This Row],[Likes]]+Table1_21718[[#This Row],[Shares]]+Table1_21718[[#This Row],[Comments]])/Table1_21718[[#This Row],[Impressions]] -> 0.070272021 | R8: =Table1_21718[[#This Row],[Likes]]+Table1_21718[[#This Row],[Shares]]+Table1_21718[[#This Row],[Comments]] -> 4340
A9: P008 | B9: YouTube | C9: 45486 | D9: Image | E9: Check out our latest image on youtube! | F9: 3929 | G9: 262 | H9: 278 | I9: 43219 | J9: 42841 | K9: 39 | L9: #EVRevolution | O9: SustainabilityDrive | P9: SustainabilityDrive | Q9: =(Table1_21718[[#This Row],[Likes]]+Table1_21718[[#This Row],[Shares]]+Table1_21718[[#This Row],[Comments]])/Table1_21718[[#This Row],[Impressions]] -> 0.1034036 | R9: =Table1_21718[[#This Row],[Likes]]+Table1_21718[[#This Row],[Shares]]+Table1_21718[[#This Row],[Comments]] -> 4469
A10: P009 | B10: Facebook | C10: 45534 | D10: Text | E10: Check out our latest text on facebook! | F10: 3784 | G10: 808 | H10: 404 | I10: 56760 | J10: 56343 | K10: 131 | L10: #TeslaCoInnovation | O10: ModelYCampaign | P10: ModelYCampaign | Q10: =(Table1_21718[[#This Row],[Likes]]+Table1_21718[[#This Row],[Shares]]+Table1_21718[[#This Row],[Comments]])/Table1_21718[[#This Row],[Impressions]] -> 0.088019732 | R10: =Table1_21718[[#This Row],[Likes]]+Table1_21718[[#This Row],[Shares]]+Table1_21718[[#This Row],[Comments]] -> 4996
A11: P010 | B11: Facebook | C11: 45727 | D11: Image | E11: Check out our latest image on facebook! | F11: 4241 | G11: 902 | H11: 47 | I11: 72097 | J11: 71598 | K11: 167 | L11: #TeslaCoInnovation | O11: ModelYCampaign | P11: ModelYCampaign | Q11: =(Table1_21718[[#This Row],[Likes]]+Table1_21718[[#This Row],[Shares]]+Table1_21718[[#This Row],[Comments]])/Table1_21718[[#This Row],[Impressions]] -> 0.071986352 | R11: =Table1_21718[[#This Row],[Likes]]+Table1_21718[[#This Row],[Shares]]+Table1_21718[[#This Row],[Comments]] -> 5190
A12: P011 | B12: Instagram | C12: 45690 | D12: Story | E12: Check out our latest story on instagram! | F12: 1792 | G12: 614 | H12: 497 | I12: 25088 | J12: 24675 | K12: 65 | L12: #FutureOfDriving | O12: SustainabilityDrive | P12: SustainabilityDrive | Q12: =(Table1_21718[[#This Row],[Likes]]+Table1_21718[[#This Row],[Shares]]+Table1_21718[[#This Row],[Comments]])/Table1_21718[[#This Row],[Impressions]] -> 0.11571269 | R12: =Table1_21718[[#This Row],[Likes]]+Table1_21718[[#This Row],[Shares]]+Table1_21718[[#This Row],[Comments]] -> 2903
A13: P012 | B13: Facebook | C13: 45494 | D13: Reel | E13: Check out our latest reel on facebook! | F13: 1946 | G13: 686 | H13: 377 | I13: 23352 | J13: 22982 | K13: 213 | L13: #FutureOfDriving | O13: FSDUpdate | P13: FSDUpdate | Q13: =(Table1_21718[[#This Row],[Likes]]+Table1_21718[[#This Row],[Shares]]+Table1_21718[[#This Row],[Comments]])/Table1_21718[[#This Row],[Impressions]] -> 0.12885406 | R13: =Table1_21718[[#This Row],[Likes]]+Table1_21718[[#This Row],[Shares]]+Table1_21718[[#This Row],[Comments]] -> 3009
A14: P013 | B14: YouTube | C14: 45614 | D14: Carousel | E14: Check out our latest carousel on youtube! | F14: 1171 | G14: 286 | H14: 231 | I14: 22249 | J14: 21282 | K14: 114 | L14: #EVRevolution | O14: CybertruckLaunch | P14: CybertruckLaunch | Q14: =(Table1_21718[[#This Row],[Likes]]+Table1_21718[[#This Row],[Shares]]+Table1_21718[[#This Row],[Comments]])/Table1_21718[[#This Row],[Impressions]] -> 0.075868578 | R14: =Table1_21718[[#This Row],[Likes]]+Table1_21718[[#This Row],[Shares]]+Table1_21718[[#This Row],[Comments]] -> 1688
A15: P014 | B15: Facebook | C15: 45704 | D15: Story | E15: Check out our latest story on facebook! | F15: 4242 | G15: 555 | H15: 131 | I15: 33936 | J15: 33802 | K15: 265 | L15: #FutureOfDriving | P15: SustainabilityDrive | Q15: =(Table1_21718[[#This Row],[Likes]]+Table1_21718[[#This Row],[Shares]]+Table1_21718[[#This Row],[Comments]])/Table1_21718[[#This Row],[Impressions]] -> 0.14521452 | R15: =Table1_21718[[#This Row],[Likes]]+Table1_21718[[#This Row],[Shares]]+Table1_21718[[#This Row],[Comments]] -> 4928
A16: P015 | B16: Facebook | C16: 45589 | D16: Video | E16: Check out our latest video on facebook! | F16: 3888 | G16: 604 | H16: 128 | I16: 77760 | J16: 77167 | K16: 20 | L16: #FutureOfDriving | O16: CybertruckLaunch | P16: CybertruckLaunch | Q16: =(Table1_21718[[#This Row],[Likes]]+Table1_21718[[#This Row],[Shares]]+Table1_21718[[#This Row],[Comments]])/Table1_21718[[#This Row],[Impressions]] -> 0.05941358 | R16: =Table1_21718[[#This Row],[Likes]]+Table1_21718[[#This Row],[Shares]]+Table1_21718[[#This Row],[Comments]] -> 4620
A17: P016 | B17: Facebook | C17: 45530 | D17: Text | E17: Check out our latest text on facebook! | F17: 3452 | G17: 377 | H17: 360 | I17: 55232 | J17: 55075 | K17: 87 | L17: #FutureOfDriving | O17: FSDUpdate | P17: FSDUpdate | Q17: =(Table1_21718[[#This Row],[Likes]]+Table1_21718[[#This Row],[Shares]]+Table1_21718[[#This Row],[Comments]])/Table1_21718[[#This Row],[Impressions]] -> 0.075843714 | R17: =Table1_21718[[#This Row],[Likes]]+Table1_21718[[#This Row],[Shares]]+Table1_21718[[#This Row],[Comments]] -> 4189
A18: P017 | B18: Facebook | C18: 45782 | D18: Text | E18: Check out our latest text on facebook! | F18: 4441 | G18: 511 | H18: 70 | I18: 53292 | J18: 53082 | K18: 159 | L18: #EVRevolution | O18: SustainabilityDrive | P18: SustainabilityDrive | Q18: =(Table1_21718[[#This Row],[Likes]]+Table1_21718[[#This Row],[Shares]]+Table1_21718[[#This Row],[Comments]])/Table1_21718[[#This Row],[Impressions]] -> 0.094235533 | R18: =Table1_21718[[#This Row],[Likes]]+Table1_21718[[#This Row],[Shares]]+Table1_21718[[#This Row],[Comments]] -> 5022
A19: P018 | B19: Instagram | C19: 45523 | D19: Reel | E19: Check out our latest reel on instagram! | F19: 3000 | G19: 382 | H19: 325 | I19: 36000 | J19: 35819 | K19: 19 | L19: #FutureOfDriving | O19: CybertruckLaunch | P19: CybertruckLaunch | Q19: =(Table1_21718[[#This Row],[Likes]]+Table1_21718[[#This Row],[Shares]]+Table1_21718[[#This Row],[Comments]])/Table1_21718[[#This Row],[Impressions]] -> 0.10297222 | R19: =Table1_21718[[#This Row],[Likes]]+Table1_21718[[#This Row],[Shares]]+Table1_21718[[#This Row],[Comments]] -> 3707
A20: P019 | B20: Instagram | C20: 45466 | D20: Video | E20: Check out our latest video on instagram! | F20: 1071 | G20: 519 | H20: 22 | I20: 16065 | J20: 15865 | K20: 103 | L20: #TeslaCoInnovation | O20: SustainabilityDrive | P20: SustainabilityDrive | Q20: =(Table1_21718[[#This Row],[Likes]]+Table1_21718[[#This Row],[Shares]]+Table1_21718[[#This Row],[Comments]])/Table1_21718[[#This Row],[Impressions]] -> 0.10034236 | R20: =Table1_21718[[#This Row],[Likes]]+Table1_21718[[#This Row],[Shares]]+Table1_21718[[#This Row],[Comments]] -> 1612
A21: P020 | B21: Instagram | C21: 45544 | D21: Carousel | E21: Check out our latest carousel on instagram! | F21: 4054 | G21: 488 | H21: 373 | I21: 77026 | J21: 76881 | K21: 25 | L21: #TeslaCoInnovation | O21: CybertruckLaunch | P21: CybertruckLaunch | Q21: =(Table1_21718[[#This Row],[Likes]]+Table1_21718[[#This Row],[Shares]]+Table1_21718[[#This Row],[Comments]])/Table1_21718[[#This Row],[Impressions]] -> 0.063809623 | R21: =Table1_21718[[#This Row],[Likes]]+Table1_21718[[#This Row],[Shares]]+Table1_21718[[#This Row],[Comments]] -> 4915
A22: P021 | B22: Instagram | C22: 45661 | D22: Reel | E22: Check out our latest reel on instagram! | F22: 4838 | G22: 640 | H22: 128 | I22: 72570 | J22: 72396 | K22: 83 | L22: #FutureOfDriving | O22: SustainabilityDrive | P22: SustainabilityDrive | Q22: =(Table1_21718[[#This Row],[Likes]]+Table1_21718[[#This Row],[Shares]]+Table1_21718[[#This Row],[Comments]])/Table1_21718[[#This Row],[Impressions]] -> 0.077249552 | R22: =Table1_21718[[#This Row],[Likes]]+Table1_21718[[#This Row],[Shares]]+Table1_21718[[#This Row],[Comments]] -> 5606
A23: P022 | B23: Facebook | C23: 45715 | D23: Text | E23: Check out our latest text on facebook! | F23: 1570 | G23: 187 | H23: 260 | I23: 25120 | J23: 24613 | K23: 133 | L23: #TeslaCoInnovation | O23: SustainabilityDrive | P23: SustainabilityDrive | Q23: =(Table1_21718[[#This Row],[Likes]]+Table1_21718[[#This Row],[Shares]]+Table1_21718[[#This Row],[Comments]])/Table1_21718[[#This Row],[Impressions]] -> 0.080294586 | R23: =Table1_21718[[#This Row],[Likes]]+Table1_21718[[#This Row],[Shares]]+Table1_21718[[#This Row],[Comments]] -> 2017
A24: P023 | B24: Facebook | C24: 45602 | D24: Video | E24: Check out our latest video on facebook! | F24: 1606 | G24: 547 | H24: 316 | I24: 32120 | J24: 31736 | K24: 225 | L24: #TeslaCoInnovation | M24: #AnytimeIsTeslaTime | O24: ModelYCampaign | P24: ModelYCampaign | Q24: =(Table1_21718[[#This Row],[Likes]]+Table1_21718[[#This Row],[Shares]]+Table1_21718[[#This Row],[Comments]])/Table1_21718[[#This Row],[Impressions]] -> 0.076867995 | R24: =Table1_21718[[#This Row],[Likes]]+Table1_21718[[#This Row],[Shares]]+Table1_21718[[#This Row],[Comments]] -> 2469
A25: P024 | B25: Facebook | C25: 45680 | D25: Video | E25: Check out our latest video on facebook! | F25: 3961 | G25: 761 | H25: 131 | I25: 67337 | J25: 66615 | K25: 161 | L25: #FutureOfDriving | O25: FSDUpdate | P25: FSDUpdate | Q25: =(Table1_21718[[#This Row],[Likes]]+Table1_21718[[#This Row],[Shares]]+Table1_21718[[#This Row],[Comments]])/Table1_21718[[#This Row],[Impressions]] -> 0.072070333 | R25: =Table1_21718[[#This Row],[Likes]]+Table1_21718[[#This Row],[Shares]]+Table1_21718[[#This Row],[Comments]] -> 4853
A26: P025 | B26: Twitter | C26: 45757 | D26: Carousel | E26: Check out our latest carousel on twitter! | F26: 3128 | G26: 211 | H26: 197 | I26: 59432 | J26: 59182 | K26: 238 | L26: #EVRevolution | P26: CybertruckLaunch | Q26: =(Table1_21718[[#This Row],[Likes]]+Table1_21718[[#This Row],[Shares]]+Table1_21718[[#This Row],[Comments]])/Table1_21718[[#This Row],[Impressions]] -> 0.059496568 | R26: =Table1_21718[[#This Row],[Likes]]+Table1_21718[[#This Row],[Shares]]+Table1_21718[[#This Row],[Comments]] -> 3536
A27: P026 | B27: YouTube | C27: 45752 | D27: Reel | E27: Check out our latest reel on youtube! | F27: 3009 | G27: 413 | H27: 358 | I27: 42126 | J27: 41309 | K27: 211 | L27: #FutureOfDriving | O27: ModelYCampaign | P27: ModelYCampaign | Q27: =(Table1_21718[[#This Row],[Likes]]+Table1_21718[[#This Row],[Shares]]+Table1_21718[[#This Row],[Comments]])/Table1_21718[[#This Row],[Impressions]] -> 0.089730808 | R27: =Table1_21718[[#This Row],[Likes]]+Table1_21718[[#This Row],[Shares]]+Table1_21718[[#This Row],[Comments]] -> 3780
A28: P027 | B28: YouTube | C28: 45552 | D28: Text | E28: Check out our latest text on youtube! | F28: 2076 | G28: 195 | H28: 104 | I28: 33216 | J28: 32244 | K28: 51 | L28: #FutureOfDriving | O28: SustainabilityDrive | P28: SustainabilityDrive | Q28: =(Table1_21718[[#This Row],[Likes]]+Table1_21718[[#This Row],[Shares]]+Table1_21718[[#This Row],[Comments]])/Table1_21718[[#This Row],[Impressions]] -> 0.071501686 | R28: =Table1_21718[[#This Row],[Likes]]+Table1_21718[[#This Row],[Shares]]+Table1_21718[[#This Row],[Comments]] -> 2375
A29: P028 | B29: Instagram | C29: 45720 | D29: Video | E29: Check out our latest video on instagram! | F29: 432 | G29: 624 | H29: 123 | I29: 6912 | J29: 6259 | K29: 79 | L29: #FutureOfDriving | O29: SustainabilityDrive | P29: SustainabilityDrive | Q29: =(Table1_21718[[#This Row],[Likes]]+Table1_21718[[#This Row],[Shares]]+Table1_21718[[#This Row],[Comments]])/Table1_21718[[#This Row],[Impressions]] -> 0.17057292 | R29: =Table1_21718[[#This Row],[Likes]]+Table1_21718[[#This Row],[Shares]]+Table1_21718[[#This Row],[Comments]] -> 1179
A30: P029 | B30: Instagram | C30: 45688 | D30: Carousel | E30: Check out our latest carousel on instagram! | F30: 2566 | G30: 118 | H30: 37 | I30: 12830 | J30: 12264 | K30: 221 | L30: #FutureOfDriving | O30: FSDUpdate | P30: FSDUpdate | Q30: =(Table1_21718[[#This Row],[Likes]]+Table1_21718[[#This Row],[Shares]]+Table1_21718[[#This Row],[Comments]])/Table1_21718[[#This Row],[Impressions]] -> 0.21208106 | R30: =Table1_21718[[#This Row],[Likes]]+Table1_21718[[#This Row],[Shares]]+Table1_21718[[#This Row],[Comments]] -> 2721
A31: P030 | B31: Instagram | C31: 45713 | D31: Video | E31: Check out our latest video on instagram! | F31: 3095 | G31: 39 | H31: 78 | I31: 55710 | J31: 54808 | K31: 93 | L31: #EVRevolution | P31: CybertruckLaunch | Q31: =(Table1_21718[[#This Row],[Likes]]+Table1_21718[[#This Row],[Shares]]+Table1_21718[[#This Row],[Comments]])/Table1_21718[[#This Row],[Impressions]] -> 0.057655717 | R31: =Table1_21718[[#This Row],[Likes]]+Table1_21718[[#This Row],[Shares]]+Table1_21718[[#This Row],[Comments]] -> 3212
A32: P031 | B32: Instagram | C32: 45642 | D32: Text | E32: Check out our latest text on instagram! | F32: 438 | G32: 153 | H32: 275 | I32: 3066 | J32: 2701 | K32: 282 | L32: #TeslaCoInnovation | O32: ModelYCampaign | P32: ModelYCampaign | Q32: =(Table1_21718[[#This Row],[Likes]]+Table1_21718[[#This Row],[Shares]]+Table1_21718[[#This Row],[Comments]])/Table1_21718[[#This Row],[Impressions]] -> 0.28245271 | R32: =Table1_21718[[#This Row],[Likes]]+Table1_21718[[#This Row],[Shares]]+Table1_21718[[#This Row],[Comments]] -> 866
A33: P032 | B33: Twitter | C33: 45504 | D33: Carousel | E33: Check out our latest carousel on twitter! | F33: 2278 | G33: 10 | H33: 321 | I33: 13668 | J33: 12676 | K33: 275 | L33: #EVRevolution | O33: CybertruckLaunch | P33: CybertruckLaunch | Q33: =(Table1_21718[[#This Row],[Likes]]+Table1_21718[[#This Row],[Shares]]+Table1_21718[[#This Row],[Comments]])/Table1_21718[[#This Row],[Impressions]] -> 0.19088382 | R33: =Table1_21718[[#This Row],[Likes]]+Table1_21718[[#This Row],[Shares]]+Table1_21718[[#This Row],[Comments]] -> 2609
A34: P033 | B34: Facebook | C34: 45525 | D34: Image | E34: Check out our latest image on facebook! | F34: 1407 | G34: 400 | H34: 351 | I34: 16884 | J34: 15954 | K34: 113 | L34: #TeslaCoInnovation | O34: CybertruckLaunch | P34: CybertruckLaunch | Q34: =(Table1_21718[[#This Row],[Likes]]+Table1_21718[[#This Row],[Shares]]+Table1_21718[[#This Row],[Comments]])/Table1_21718[[#This Row],[Impressions]] -> 0.12781331 | R34: =Table1_21718[[#This Row],[Likes]]+Table1_21718[[#This Row],[Shares]]+Table1_21718[[#This Row],[Comments]] -> 2158
A35: P034 | B35: Facebook | C35: 45742 | D35: Text | E35: Check out our latest text on facebook! | F35: 1652 | G35: 89 | H35: 357 | I35: 29736 | J35: 28771 | K35: 215 | L35: #TeslaCoInnovation | O35: FSDUpdate | P35: FSDUpdate | Q35: =(Table1_21718[[#This Row],[Likes]]+Table1_21718[[#This Row],[Shares]]+Table1_21718[[#This Row],[Comments]])/Table1_21718[[#This Row],[Impressions]] -> 0.07055421 | R35: =Table1_21718[[#This Row],[Likes]]+Table1_21718[[#This Row],[Shares]]+Table1_21718[[#This Row],[Comments]] -> 2098
A36: P035 | B36: Instagram | C36: 45626 | D36: Video | E36: Check out our latest video on instagram! | F36: 3775 | G36: 16 | H36: 239 | I36: 33975 | J36: 33310 | K36: 271 | L36: #FutureOfDriving | O36: ModelYCampaign | P36: ModelYCampaign | Q36: =(Table1_21718[[#This Row],[Likes]]+Table1_21718[[#This Row],[Shares]]+Table1_21718[[#This Row],[Comments]])/Table1_21718[[#This Row],[Impressions]] -> 0.11861663 | R36: =Table1_21718[[#This Row],[Likes]]+Table1_21718[[#This Row],[Shares]]+Table1_21718[[#This Row],[Comments]] -> 4030
A37: P036 | B37: Instagram | C37: 45766 | D37: Story | E37: Check out our latest story on instagram! | F37: 4518 | G37: 285 | H37: 383 | I37: 67770 | J37: 67621 | K37: 31 | L37: #EVRevolution | O37: ModelYCampaign | P37: ModelYCampaign | Q37: =(Table1_21718[[#This Row],[Likes]]+Table1_21718[[#This Row],[Shares]]+Table1_21718[[#This Row],[Comments]])/Table1_21718[[#This Row],[Impressions]] -> 0.076523535 | R37: =Table1_21718[[#This Row],[Likes]]+Table1_21718[[#This Row],[Shares]]+Table1_21718[[#This Row],[Comments]] -> 5186
A38: P037 | B38: Facebook | C38: 45663 | D38: Carousel | E38: Check out our latest carousel on facebook! | F38: 3024 | G38: 925 | H38: 350 | I38: 24192 | J38: 23518 | K38: 36 | L38: #EVRevolution | O38: ModelYCampaign | P38: ModelYCampaign | Q38: =(Table1_21718[[#This Row],[Likes]]+Table1_21718[[#This Row],[Shares]]+Table1_21718[[#This Row],[Comments]])/Table1_21718[[#This Row],[Impressions]] -> 0.17770337 | R38: =Table1_21718[[#This Row],[Likes]]+Table1_21718[[#This Row],[Shares]]+Table1_21718[[#This Row],[Comments]] -> 4299
A39: P038 | B39: YouTube | C39: 45705 | D39: Reel | E39: Check out our latest reel on youtube! | F39: 3138 | G39: 123 | H39: 291 | I39: 28242 | J39: 27550 | K39: 87 | L39: #TeslaCoInnovation | O39: SustainabilityDrive | P39: SustainabilityDrive | Q39: =(Table1_21718[[#This Row],[Likes]]+Table1_21718[[#This Row],[Shares]]+Table1_21718[[#This Row],[Comments]])/Table1_21718[[#This Row],[Impressions]] -> 0.12577013 | R39: =Table1_21718[[#This Row],[Likes]]+Table1_21718[[#This Row],[Shares]]+Table1_21718[[#This Row],[Comments]] -> 3552
A40: P039 | B40: Facebook | C40: 45621 | D40: Image | E40: Check out our latest image on facebook! | F40: 3564 | G40: 629 | H40: 177 | I40: 60588 | J40: 59627 | K40: 92 | L40: #TeslaCoInnovation | P40: ModelYCampaign | Q40: =(Table1_21718[[#This Row],[Likes]]+Table1_21718[[#This Row],[Shares]]+Table1_21718[[#This Row],[Comments]])/Table1_21718[[#This Row],[Impressions]] -> 0.072126494 | R40: =Table1_21718[[#This Row],[Likes]]+Table1_21718[[#This Row],[Shares]]+Table1_21718[[#This Row],[Comments]] -> 4370
...

Sheet Task 5
A1: Post ID | B1: Platform | C1: Date | D1: Content Type | E1: Post Text | F1: Likes | G1: Shares | H1: Comments | I1: Impressions | J1: Reach | K1: Clicks | L1: Hashtags Used.1 | M1: Hashtags Used.2 | N1: Hashtags Used.3 | O1: Campaign_Name | P1: Campaign_Name_Filled | Q1: Engagement Rate | R1: Total Engagement
A2: P001 | B2: Twitter | C2: 45649 | D2: Reel | E2: Check out our latest reel on twitter! | F2: 1461 | G2: 184 | H2: 344 | I2: 21915 | J2: 21675 | K2: 15 | L2: #FutureOfDriving | M2: #AnytimeIsTeslaTime | O2: CybertruckLaunch | P2: CybertruckLaunch | Q2: =(Table1_217[[#This Row],[Likes]]+Table1_217[[#This Row],[Shares]]+Table1_217[[#This Row],[Comments]])/Table1_217[[#This Row],[Impressions]] -> 0.090759754 | R2: =Table1_217[[#This Row],[Likes]]+Table1_217[[#This Row],[Shares]]+Table1_217[[#This Row],[Comments]] -> 1989
A3: P002 | B3: Twitter | C3: 45750 | D3: Text | E3: Check out our latest text on twitter! | F3: 4054 | G3: 389 | H3: 493 | I3: 64864 | J3: 64383 | K3: 117 | L3: #TeslaCoInnovation | M3: #BetterWithTesla | O3: ModelYCampaign | P3: ModelYCampaign | Q3: =(Table1_217[[#This Row],[Likes]]+Table1_217[[#This Row],[Shares]]+Table1_217[[#This Row],[Comments]])/Table1_217[[#This Row],[Impressions]] -> 0.076097681 | R3: =Table1_217[[#This Row],[Likes]]+Table1_217[[#This Row],[Shares]]+Table1_217[[#This Row],[Comments]] -> 4936 | T3: Campaign_Name | U3: Sum of Impressions | V3: Sum of Likes | W3: Sum of Clicks | X3: Average of Impressions | Y3: Average of Likes2 | Z3: Average of Clicks2 | AA3: Sum of Engagement Rate | AB3: Average of Engagement Rate | AD3: Campaign Name | AE3: Ad_Spend | AF3: ROI | AG3: Sum of Total Engagement
A4: P003 | B4: YouTube | C4: 45789 | D4: Reel | E4: Check out our latest reel on youtube! | F4: 2795 | G4: 105 | H4: 49 | I4: 53105 | J4: 52307 | K4: 204 | L4: #TeslaCoInnovation | O4: FSDUpdate | P4: FSDUpdate | Q4: =(Table1_217[[#This Row],[Likes]]+Table1_217[[#This Row],[Shares]]+Table1_217[[#This Row],[Comments]])/Table1_217[[#This Row],[Impressions]] -> 0.055531494 | R4: =Table1_217[[#This Row],[Likes]]+Table1_217[[#This Row],[Shares]]+Table1_217[[#This Row],[Comments]] -> 2949 | T4: CybertruckLaunch | U4: 2426285 | V4: 189114 | W4: 9604 | X4: 35680.662 | Y4: 2781.0882 | Z4: 141.23529 | AA4: 10.804927 | AB4: 0.15889598 | AD4: CybertruckLaunch | AE4: =VLOOKUP(T4, 'Campaign Metadata'!A1:G5, 5,FALSE) -> 150000 | AF4: =GETPIVOTDATA("Sum of Total Engagement",$T$10,"Campaign_Name_Filled","CybertruckLaunch")/AE4 -> 1.6349 | AG4: =GETPIVOTDATA("Sum of Total Engagement",$T$10,"Campaign_Name_Filled","CybertruckLaunch") -> 245235
A5: P004 | B5: Instagram | C5: 45516 | D5: Story | E5: Check out our latest story on instagram! | F5: 2404 | G5: 363 | H5: 138 | I5: 19232 | J5: 18636 | K5: 128 | L5: #EVRevolution | O5: SustainabilityDrive | P5: SustainabilityDrive | Q5: =(Table1_217[[#This Row],[Likes]]+Table1_217[[#This Row],[Shares]]+Table1_217[[#This Row],[Comments]])/Table1_217[[#This Row],[Impressions]] -> 0.15105033 | R5: =Table1_217[[#This Row],[Likes]]+Table1_217[[#This Row],[Shares]]+Table1_217[[#This Row],[Comments]] -> 2905 | T5: FSDUpdate | U5: 2266053 | V5: 183346 | W5: 10032 | X5: 33821.687 | Y5: 2736.5075 | Z5: 149.73134 | AA5: 9.6479456 | AB5: 0.14399919 | AD5: FSDUpdate | AE5: =VLOOKUP(T5, 'Campaign Metadata'!A2:G6, 5,FALSE) -> 250000 | AF5: =GETPIVOTDATA("Sum of Total Engagement",$T$10,"Campaign_Name_Filled","CybertruckLaunch")/AE5 -> 0.98094 | AG5: =GETPIVOTDATA("Sum of Total Engagement",$T$10,"Campaign_Name_Filled","FSDUpdate") -> 242853
A6: P005 | B6: YouTube | C6: 45469 | D6: Reel | E6: Check out our latest reel on youtube! | F6: 3557 | G6: 687 | H6: 424 | I6: 71140 | J6: 70701 | K6: 224 | L6: #EVRevolution | M6: #TeslaCoInnovation | O6: CybertruckLaunch | P6: CybertruckLaunch | Q6: =(Table1_217[[#This Row],[Likes]]+Table1_217[[#This Row],[Shares]]+Table1_217[[#This Row],[Comments]])/Table1_217[[#This Row],[Impressions]] -> 0.065617093 | R6: =Table1_217[[#This Row],[Likes]]+Table1_217[[#This Row],[Shares]]+Table1_217[[#This Row],[Comments]] -> 4668 | T6: ModelYCampaign | U6: 2632016 | V6: 206959 | W6: 12287 | X6: 34631.789 | Y6: 2723.1447 | Z6: 161.67105 | AA6: 10.620021 | AB6: 0.13973712 | AD6: ModelYCampaign | AE6: =VLOOKUP(T6, 'Campaign Metadata'!A3:G7, 5,FALSE) -> 200000 | AF6: =GETPIVOTDATA("Sum of Total Engagement",$T$10,"Campaign_Name_Filled","CybertruckLaunch")/AE6 -> 1.226175 | AG6: =GETPIVOTDATA("Sum of Total Engagement",$T$10,"Campaign_Name_Filled","ModelYCampaign") -> 274774
A7: P006 | B7: Facebook | C7: 45596 | D7: Carousel | E7: Check out our latest carousel on facebook! | F7: 2945 | G7: 930 | H7: 355 | I7: 23560 | J7: 23275 | K7: 256 | L7: #TeslaCoInnovation | O7: ModelYCampaign | P7: ModelYCampaign | Q7: =(Table1_217[[#This Row],[Likes]]+Table1_217[[#This Row],[Shares]]+Table1_217[[#This Row],[Comments]])/Table1_217[[#This Row],[Impressions]] -> 0.1795416 | R7: =Table1_217[[#This Row],[Likes]]+Table1_217[[#This Row],[Shares]]+Table1_217[[#This Row],[Comments]] -> 4230 | T7: SustainabilityDrive | U7: 3069799 | V7: 240572 | W7: 13443 | X7: 34492.124 | Y7: 2703.0562 | Z7: 151.04494 | AA7: 13.411924 | AB7: 0.15069577 | AD7: SustainabilityDrive | AE7: =VLOOKUP(T7, 'Campaign Metadata'!A4:G8, 5,FALSE) -> 180000 | AF7: =GETPIVOTDATA("Sum of Total Engagement",$T$10,"Campaign_Name_Filled","CybertruckLaunch")/AE7 -> 1.3624167 | AG7: =GETPIVOTDATA("Sum of Total Engagement",$T$10,"Campaign_Name_Filled","SustainabilityDrive") -> 320271
A8: P007 | B8: Twitter | C8: 45467 | D8: Carousel | E8: Check out our latest carousel on twitter! | F8: 3860 | G8: 201 | H8: 279 | I8: 61760 | J8: 61660 | K8: 235 | L8: #TeslaCoInnovation | O8: ModelYCampaign | P8: ModelYCampaign | Q8: =(Table1_217[[#This Row],[Likes]]+Table1_217[[#This Row],[Shares]]+Table1_217[[#This Row],[Comments]])/Table1_217[[#This Row],[Impressions]] -> 0.070272021 | R8: =Table1_217[[#This Row],[Likes]]+Table1_217[[#This Row],[Shares]]+Table1_217[[#This Row],[Comments]] -> 4340 | T8: Grand Total | U8: 10394153 | V8: 819991 | W8: 45366 | X8: 34647.177 | Y8: 2733.3033 | Z8: 151.22 | AA8: 44.484817 | AB8: 0.14828272
A9: P008 | B9: YouTube | C9: 45486 | D9: Image | E9: Check out our latest image on youtube! | F9: 3929 | G9: 262 | H9: 278 | I9: 43219 | J9: 42841 | K9: 39 | L9: #EVRevolution | O9: SustainabilityDrive | P9: SustainabilityDrive | Q9: =(Table1_217[[#This Row],[Likes]]+Table1_217[[#This Row],[Shares]]+Table1_217[[#This Row],[Comments]])/Table1_217[[#This Row],[Impressions]] -> 0.1034036 | R9: =Table1_217[[#This Row],[Likes]]+Table1_217[[#This Row],[Shares]]+Table1_217[[#This Row],[Comments]] -> 4469
A10: P009 | B10: Facebook | C10: 45534 | D10: Text | E10: Check out our latest text on facebook! | F10: 3784 | G10: 808 | H10: 404 | I10: 56760 | J10: 56343 | K10: 131 | L10: #TeslaCoInnovation | O10: ModelYCampaign | P10: ModelYCampaign | Q10: =(Table1_217[[#This Row],[Likes]]+Table1_217[[#This Row],[Shares]]+Table1_217[[#This Row],[Comments]])/Table1_217[[#This Row],[Impressions]] -> 0.088019732 | R10: =Table1_217[[#This Row],[Likes]]+Table1_217[[#This Row],[Shares]]+Table1_217[[#This Row],[Comments]] -> 4996 | T10: Row Labels | U10: Sum of Impressions | V10: Sum of Clicks | W10: Sum of Likes | X10: Average of Impressions | Y10: Average of Clicks | Z10: Average of Likes | AA10: Sum of Total Engagement | AB10: Average of Engagement Rate
A11: P010 | B11: Facebook | C11: 45727 | D11: Image | E11: Check out our latest image on facebook! | F11: 4241 | G11: 902 | H11: 47 | I11: 72097 | J11: 71598 | K11: 167 | L11: #TeslaCoInnovation | O11: ModelYCampaign | P11: ModelYCampaign | Q11: =(Table1_217[[#This Row],[Likes]]+Table1_217[[#This Row],[Shares]]+Table1_217[[#This Row],[Comments]])/Table1_217[[#This Row],[Impressions]] -> 0.071986352 | R11: =Table1_217[[#This Row],[Likes]]+Table1_217[[#This Row],[Shares]]+Table1_217[[#This Row],[Comments]] -> 5190 | T11: CybertruckLaunch | U11: 2426285 | V11: 9604 | W11: 189114 | X11: 35680.662 | Y11: 141.23529 | Z11: 2781.0882 | AA11: 245235
A12: P011 | B12: Instagram | C12: 45690 | D12: Story | E12: Check out our latest story on instagram! | F12: 1792 | G12: 614 | H12: 497 | I12: 25088 | J12: 24675 | K12: 65 | L12: #FutureOfDriving | O12: SustainabilityDrive | P12: SustainabilityDrive | Q12: =(Table1_217[[#This Row],[Likes]]+Table1_217[[#This Row],[Shares]]+Table1_217[[#This Row],[Comments]])/Table1_217[[#This Row],[Impressions]] -> 0.11571269 | R12: =Table1_217[[#This Row],[Likes]]+Table1_217[[#This Row],[Shares]]+Table1_217[[#This Row],[Comments]] -> 2903 | T12: FSDUpdate | U12: 2266053 | V12: 10032 | W12: 183346 | X12: 33821.687 | Y12: 149.73134 | Z12: 2736.5075 | AA12: 242853
A13: P012 | B13: Facebook | C13: 45494 | D13: Reel | E13: Check out our latest reel on facebook! | F13: 1946 | G13: 686 | H13: 377 | I13: 23352 | J13: 22982 | K13: 213 | L13: #FutureOfDriving | O13: FSDUpdate | P13: FSDUpdate | Q13: =(Table1_217[[#This Row],[Likes]]+Table1_217[[#This Row],[Shares]]+Table1_217[[#This Row],[Comments]])/Table1_217[[#This Row],[Impressions]] -> 0.12885406 | R13: =Table1_217[[#This Row],[Likes]]+Table1_217[[#This Row],[Shares]]+Table1_217[[#This Row],[Comments]] -> 3009 | T13: ModelYCampaign | U13: 2632016 | V13: 12287 | W13: 206959 | X13: 34631.789 | Y13: 161.67105 | Z13: 2723.1447 | AA13: 274774
A14: P013 | B14: YouTube | C14: 45614 | D14: Carousel | E14: Check out our latest carousel on youtube! | F14: 1171 | G14: 286 | H14: 231 | I14: 22249 | J14: 21282 | K14: 114 | L14: #EVRevolution | O14: CybertruckLaunch | P14: CybertruckLaunch | Q14: =(Table1_217[[#This Row],[Likes]]+Table1_217[[#This Row],[Shares]]+Table1_217[[#This Row],[Comments]])/Table1_217[[#This Row],[Impressions]] -> 0.075868578 | R14: =Table1_217[[#This Row],[Likes]]+Table1_217[[#This Row],[Shares]]+Table1_217[[#This Row],[Comments]] -> 1688 | T14: SustainabilityDrive | U14: 3069799 | V14: 13443 | W14: 240572 | X14: 34492.124 | Y14: 151.04494 | Z14: 2703.0562 | AA14: 320271
A15: P014 | B15: Facebook | C15: 45704 | D15: Story | E15: Check out our latest story on facebook! | F15: 4242 | G15: 555 | H15: 131 | I15: 33936 | J15: 33802 | K15: 265 | L15: #FutureOfDriving | P15: SustainabilityDrive | Q15: =(Table1_217[[#This Row],[Likes]]+Table1_217[[#This Row],[Shares]]+Table1_217[[#This Row],[Comments]])/Table1_217[[#This Row],[Impressions]] -> 0.14521452 | R15: =Table1_217[[#This Row],[Likes]]+Table1_217[[#This Row],[Shares]]+Table1_217[[#This Row],[Comments]] -> 4928 | T15: Grand Total | U15: 10394153 | V15: 45366 | W15: 819991 | X15: 34647.177 | Y15: 151.22 | Z15: 2733.3033 | AA15: 1083133
A16: P015 | B16: Facebook | C16: 45589 | D16: Video | E16: Check out our latest video on facebook! | F16: 3888 | G16: 604 | H16: 128 | I16: 77760 | J16: 77167 | K16: 20 | L16: #FutureOfDriving | O16: CybertruckLaunch | P16: CybertruckLaunch | Q16: =(Table1_217[[#This Row],[Likes]]+Table1_217[[#This Row],[Shares]]+Table1_217[[#This Row],[Comments]])/Table1_217[[#This Row],[Impressions]] -> 0.05941358 | R16: =Table1_217[[#This Row],[Likes]]+Table1_217[[#This Row],[Shares]]+Table1_217[[#This Row],[Comments]] -> 4620
A17: P016 | B17: Facebook | C17: 45530 | D17: Text | E17: Check out our latest text on facebook! | F17: 3452 | G17: 377 | H17: 360 | I17: 55232 | J17: 55075 | K17: 87 | L17: #FutureOfDriving | O17: FSDUpdate | P17: FSDUpdate | Q17: =(Table1_217[[#This Row],[Likes]]+Table1_217[[#This Row],[Shares]]+Table1_217[[#This Row],[Comments]])/Table1_217[[#This Row],[Impressions]] -> 0.075843714 | R17: =Table1_217[[#This Row],[Likes]]+Table1_217[[#This Row],[Shares]]+Table1_217[[#This Row],[Comments]] -> 4189
A18: P017 | B18: Facebook | C18: 45782 | D18: Text | E18: Check out our latest text on facebook! | F18: 4441 | G18: 511 | H18: 70 | I18: 53292 | J18: 53082 | K18: 159 | L18: #EVRevolution | O18: SustainabilityDrive | P18: SustainabilityDrive | Q18: =(Table1_217[[#This Row],[Likes]]+Table1_217[[#This Row],[Shares]]+Table1_217[[#This Row],[Comments]])/Table1_217[[#This Row],[Impressions]] -> 0.094235533 | R18: =Table1_217[[#This Row],[Likes]]+Table1_217[[#This Row],[Shares]]+Table1_217[[#This Row],[Comments]] -> 5022
A19: P018 | B19: Instagram | C19: 45523 | D19: Reel | E19: Check out our latest reel on instagram! | F19: 3000 | G19: 382 | H19: 325 | I19: 36000 | J19: 35819 | K19: 19 | L19: #FutureOfDriving | O19: CybertruckLaunch | P19: CybertruckLaunch | Q19: =(Table1_217[[#This Row],[Likes]]+Table1_217[[#This Row],[Shares]]+Table1_217[[#This Row],[Comments]])/Table1_217[[#This Row],[Impressions]] -> 0.10297222 | R19: =Table1_217[[#This Row],[Likes]]+Table1_217[[#This Row],[Shares]]+Table1_217[[#This Row],[Comments]] -> 3707
A20: P019 | B20: Instagram | C20: 45466 | D20: Video | E20: Check out our latest video on instagram! | F20: 1071 | G20: 519 | H20: 22 | I20: 16065 | J20: 15865 | K20: 103 | L20: #TeslaCoInnovation | O20: SustainabilityDrive | P20: SustainabilityDrive | Q20: =(Table1_217[[#This Row],[Likes]]+Table1_217[[#This Row],[Shares]]+Table1_217[[#This Row],[Comments]])/Table1_217[[#This Row],[Impressions]] -> 0.10034236 | R20: =Table1_217[[#This Row],[Likes]]+Table1_217[[#This Row],[Shares]]+Table1_217[[#This Row],[Comments]] -> 1612
A21: P020 | B21: Instagram | C21: 45544 | D21: Carousel | E21: Check out our latest carousel on instagram! | F21: 4054 | G21: 488 | H21: 373 | I21: 77026 | J21: 76881 | K21: 25 | L21: #TeslaCoInnovation | O21: CybertruckLaunch | P21: CybertruckLaunch | Q21: =(Table1_217[[#This Row],[Likes]]+Table1_217[[#This Row],[Shares]]+Table1_217[[#This Row],[Comments]])/Table1_217[[#This Row],[Impressions]] -> 0.063809623 | R21: =Table1_217[[#This Row],[Likes]]+Table1_217[[#This Row],[Shares]]+Table1_217[[#This Row],[Comments]] -> 4915
A22: P021 | B22: Instagram | C22: 45661 | D22: Reel | E22: Check out our latest reel on instagram! | F22: 4838 | G22: 640 | H22: 128 | I22: 72570 | J22: 72396 | K22: 83 | L22: #FutureOfDriving | O22: SustainabilityDrive | P22: SustainabilityDrive | Q22: =(Table1_217[[#This Row],[Likes]]+Table1_217[[#This Row],[Shares]]+Table1_217[[#This Row],[Comments]])/Table1_217[[#This Row],[Impressions]] -> 0.077249552 | R22: =Table1_217[[#This Row],[Likes]]+Table1_217[[#This Row],[Shares]]+Table1_217[[#This Row],[Comments]] -> 5606
A23: P022 | B23: Facebook | C23: 45715 | D23: Text | E23: Check out our latest text on facebook! | F23: 1570 | G23: 187 | H23: 260 | I23: 25120 | J23: 24613 | K23: 133 | L23: #TeslaCoInnovation | O23: SustainabilityDrive | P23: SustainabilityDrive | Q23: =(Table1_217[[#This Row],[Likes]]+Table1_217[[#This Row],[Shares]]+Table1_217[[#This Row],[Comments]])/Table1_217[[#This Row],[Impressions]] -> 0.080294586 | R23: =Table1_217[[#This Row],[Likes]]+Table1_217[[#This Row],[Shares]]+Table1_217[[#This Row],[Comments]] -> 2017
A24: P023 | B24: Facebook | C24: 45602 | D24: Video | E24: Check out our latest video on facebook! | F24: 1606 | G24: 547 | H24: 316 | I24: 32120 | J24: 31736 | K24: 225 | L24: #TeslaCoInnovation | M24: #AnytimeIsTeslaTime | O24: ModelYCampaign | P24: ModelYCampaign | Q24: =(Table1_217[[#This Row],[Likes]]+Table1_217[[#This Row],[Shares]]+Table1_217[[#This Row],[Comments]])/Table1_217[[#This Row],[Impressions]] -> 0.076867995 | R24: =Table1_217[[#This Row],[Likes]]+Table1_217[[#This Row],[Shares]]+Table1_217[[#This Row],[Comments]] -> 2469
A25: P024 | B25: Facebook | C25: 45680 | D25: Video | E25: Check out our latest video on facebook! | F25: 3961 | G25: 761 | H25: 131 | I25: 67337 | J25: 66615 | K25: 161 | L25: #FutureOfDriving | O25: FSDUpdate | P25: FSDUpdate | Q25: =(Table1_217[[#This Row],[Likes]]+Table1_217[[#This Row],[Shares]]+Table1_217[[#This Row],[Comments]])/Table1_217[[#This Row],[Impressions]] -> 0.072070333 | R25: =Table1_217[[#This Row],[Likes]]+Table1_217[[#This Row],[Shares]]+Table1_217[[#This Row],[Comments]] -> 4853
A26: P025 | B26: Twitter | C26: 45757 | D26: Carousel | E26: Check out our latest carousel on twitter! | F26: 3128 | G26: 211 | H26: 197 | I26: 59432 | J26: 59182 | K26: 238 | L26: #EVRevolution | P26: CybertruckLaunch | Q26: =(Table1_217[[#This Row],[Likes]]+Table1_217[[#This Row],[Shares]]+Table1_217[[#This Row],[Comments]])/Table1_217[[#This Row],[Impressions]] -> 0.059496568 | R26: =Table1_217[[#This Row],[Likes]]+Table1_217[[#This Row],[Shares]]+Table1_217[[#This Row],[Comments]] -> 3536
A27: P026 | B27: YouTube | C27: 45752 | D27: Reel | E27: Check out our latest reel on youtube! | F27: 3009 | G27: 413 | H27: 358 | I27: 42126 | J27: 41309 | K27: 211 | L27: #FutureOfDriving | O27: ModelYCampaign | P27: ModelYCampaign | Q27: =(Table1_217[[#This Row],[Likes]]+Table1_217[[#This Row],[Shares]]+Table1_217[[#This Row],[Comments]])/Table1_217[[#This Row],[Impressions]] -> 0.089730808 | R27: =Table1_217[[#This Row],[Likes]]+Table1_217[[#This Row],[Shares]]+Table1_217[[#This Row],[Comments]] -> 3780
A28: P027 | B28: YouTube | C28: 45552 | D28: Text | E28: Check out our latest text on youtube! | F28: 2076 | G28: 195 | H28: 104 | I28: 33216 | J28: 32244 | K28: 51 | L28: #FutureOfDriving | O28: SustainabilityDrive | P28: SustainabilityDrive | Q28: =(Table1_217[[#This Row],[Likes]]+Table1_217[[#This Row],[Shares]]+Table1_217[[#This Row],[Comments]])/Table1_217[[#This Row],[Impressions]] -> 0.071501686 | R28: =Table1_217[[#This Row],[Likes]]+Table1_217[[#This Row],[Shares]]+Table1_217[[#This Row],[Comments]] -> 2375
A29: P028 | B29: Instagram | C29: 45720 | D29: Video | E29: Check out our latest video on instagram! | F29: 432 | G29: 624 | H29: 123 | I29: 6912 | J29: 6259 | K29: 79 | L29: #FutureOfDriving | O29: SustainabilityDrive | P29: SustainabilityDrive | Q29: =(Table1_217[[#This Row],[Likes]]+Table1_217[[#This Row],[Shares]]+Table1_217[[#This Row],[Comments]])/Table1_217[[#This Row],[Impressions]] -> 0.17057292 | R29: =Table1_217[[#This Row],[Likes]]+Table1_217[[#This Row],[Shares]]+Table1_217[[#This Row],[Comments]] -> 1179
A30: P029 | B30: Instagram | C30: 45688 | D30: Carousel | E30: Check out our latest carousel on instagram! | F30: 2566 | G30: 118 | H30: 37 | I30: 12830 | J30: 12264 | K30: 221 | L30: #FutureOfDriving | O30: FSDUpdate | P30: FSDUpdate | Q30: =(Table1_217[[#This Row],[Likes]]+Table1_217[[#This Row],[Shares]]+Table1_217[[#This Row],[Comments]])/Table1_217[[#This Row],[Impressions]] -> 0.21208106 | R30: =Table1_217[[#This Row],[Likes]]+Table1_217[[#This Row],[Shares]]+Table1_217[[#This Row],[Comments]] -> 2721
A31: P030 | B31: Instagram | C31: 45713 | D31: Video | E31: Check out our latest video on instagram! | F31: 3095 | G31: 39 | H31: 78 | I31: 55710 | J31: 54808 | K31: 93 | L31: #EVRevolution | P31: CybertruckLaunch | Q31: =(Table1_217[[#This Row],[Likes]]+Table1_217[[#This Row],[Shares]]+Table1_217[[#This Row],[Comments]])/Table1_217[[#This Row],[Impressions]] -> 0.057655717 | R31: =Table1_217[[#This Row],[Likes]]+Table1_217[[#This Row],[Shares]]+Table1_217[[#This Row],[Comments]] -> 3212
A32: P031 | B32: Instagram | C32: 45642 | D32: Text | E32: Check out our latest text on instagram! | F32: 438 | G32: 153 | H32: 275 | I32: 3066 | J32: 2701 | K32: 282 | L32: #TeslaCoInnovation | O32: ModelYCampaign | P32: ModelYCampaign | Q32: =(Table1_217[[#This Row],[Likes]]+Table1_217[[#This Row],[Shares]]+Table1_217[[#This Row],[Comments]])/Table1_217[[#This Row],[Impressions]] -> 0.28245271 | R32: =Table1_217[[#This Row],[Likes]]+Table1_217[[#This Row],[Shares]]+Table1_217[[#This Row],[Comments]] -> 866
A33: P032 | B33: Twitter | C33: 45504 | D33: Carousel | E33: Check out our latest carousel on twitter! | F33: 2278 | G33: 10 | H33: 321 | I33: 13668 | J33: 12676 | K33: 275 | L33: #EVRevolution | O33: CybertruckLaunch | P33: CybertruckLaunch | Q33: =(Table1_217[[#This Row],[Likes]]+Table1_217[[#This Row],[Shares]]+Table1_217[[#This Row],[Comments]])/Table1_217[[#This Row],[Impressions]] -> 0.19088382 | R33: =Table1_217[[#This Row],[Likes]]+Table1_217[[#This Row],[Shares]]+Table1_217[[#This Row],[Comments]] -> 2609
